#VRML_SIM R2025a utf8

EXTERNPROTO "https://raw.githubusercontent.com/cyberbotics/webots/R2025a/projects/objects/backgrounds/protos/TexturedBackground.proto"
EXTERNPROTO "https://raw.githubusercontent.com/cyberbotics/webots/R2025a/projects/objects/backgrounds/protos/TexturedBackgroundLight.proto"
EXTERNPROTO "https://raw.githubusercontent.com/cyberbotics/webots/R2025a/projects/objects/floors/protos/RectangleArena.proto"
EXTERNPROTO "https://raw.githubusercontent.com/cyberbotics/webots/R2025a/projects/appearances/protos/ThreadMetalPlate.proto"
EXTERNPROTO "https://raw.githubusercontent.com/cyberbotics/webots/R2025a/projects/appearances/protos/Roughcast.proto"
EXTERNPROTO "https://raw.githubusercontent.com/cyberbotics/webots/R2025a/projects/robots/boston_dynamics/spot/protos/Spot.proto"

WorldInfo {
  info [
    "Simulation of Boston Dynamics' Spot robot in a simple industrial environment."
    "The robot is saying hello with its right leg."
  ]
  title "Spot Robot demo"
}
Viewpoint {
  orientation 0.04099613744427168 -0.027905691555505756 -0.9987695375277819 4.3356761991844515
  position 1.053422502178661 -0.5861219361093251 1.329022052264677
  followType "None"
  followSmoothness 0
}
TexturedBackground {
  texture "factory"
  skybox FALSE
}
TexturedBackgroundLight {
  texture "factory"
}
RectangleArena {
  floorSize 10 10
  floorAppearance ThreadMetalPlate {
    textureTransform TextureTransform {
      scale 0.7 0.7
    }
  }
  wallThickness 0.1
  wallHeight 1.3
  wallAppearance Roughcast {
    colorOverride 0.662745 0.662745 0.662745
    textureTransform TextureTransform {
      scale 10 10
    }
  }
}
Solid {
  translation -2.64563 -3.85063 1.77636e-15
  children [
    Shape {
      appearance PBRAppearance {
        baseColor 0 0.6 0.7
        roughness 1
        metalness 0
      }
      geometry Box {
        size 2.9 0.1 1.9
      }
    }
  ]
  boundingObject Box {
    size 2.9 0.1 1.9
  }
}
Spot {
  translation -0.0635456 3.12986 0.624
  rotation 0 0 1 -1.5707953071795862
  controller "object_detection"
  supervisor TRUE
  frontExtension [
    DistanceSensor {
      translation 2.65098e-07 -0.02 -0.26
      rotation 0 -1 0 -1.5707953071795862
      children [
        Shape {
          appearance PBRAppearance {
          }
          geometry Box {
            size 0.03 0.03 0.03
          }
        }
      ]
      name "ds_front"
      lookupTable [
        0 0 0
        2 1000 0
      ]
      aperture 1.57
    }
    DistanceSensor {
      translation 0.05 -0.02 -0.26
      rotation 0 -1 0 -1.3089953071795861
      children [
        Shape {
          appearance PBRAppearance {
          }
          geometry Box {
            size 0.03 0.03 0.03
          }
        }
      ]
      name "ds_right"
      lookupTable [
        0 0 0
        2 1000 0
      ]
    }
    DistanceSensor {
      translation -0.05 -0.02 -0.26
      rotation 0 1 0 2.0944
      children [
        Shape {
          appearance PBRAppearance {
          }
          geometry Box {
            size 0.03 0.03 0.03
          }
        }
      ]
      name "ds_left"
      lookupTable [
        0 0 0
        2 1000 0
      ]
    }
  ]
  rearExtension [
    HingeJoint {
      jointParameters HingeJointParameters {
        axis -1 0 0
        anchor 0.17 -0.68 0.07
      }
      device [
        RotationalMotor {
          name "wheel1"
        }
      ]
      endPoint DEF WHEEL1 Solid {
        translation 0.17 -0.68 0.07
        rotation 0 1 0 1.5708
        children [
          DEF WHEEL Shape {
            appearance PBRAppearance {
            }
            geometry Cylinder {
              height 0.05
              radius 0.05
            }
          }
        ]
        name "solid(1)"
        boundingObject USE WHEEL
        physics Physics {
        }
      }
    }
    HingeJoint {
      jointParameters HingeJointParameters {
        axis -1 0 0
        anchor -0.17 -0.68 0.07
      }
      device [
        RotationalMotor {
          name "wheel2"
        }
      ]
      endPoint DEF WHEEL1 Solid {
        translation -0.17 -0.68 0.07
        rotation 0 1 0 1.5708
        children [
          DEF WHEEL Shape {
            appearance PBRAppearance {
            }
            geometry Cylinder {
              height 0.05
              radius 0.05
            }
          }
        ]
        name "Wheel2"
        boundingObject USE WHEEL
        physics Physics {
        }
      }
    }
    HingeJoint {
      jointParameters HingeJointParameters {
        axis -1 0 0
        anchor -0.17 -0.68 -0.6
      }
      device [
        RotationalMotor {
          name "wheel3"
        }
      ]
      endPoint DEF WHEEL1 Solid {
        translation -0.17000000535284604 -0.6800178430489071 -0.599912529091243
        rotation 0.7071072811859472 1.3267905276071413e-06 0.7071062811855495 3.14159
        children [
          DEF WHEEL Shape {
            appearance PBRAppearance {
            }
            geometry Cylinder {
              height 0.05
              radius 0.05
            }
          }
        ]
        name "Wheel3"
        boundingObject USE WHEEL
        physics Physics {
        }
      }
    }
    HingeJoint {
      jointParameters HingeJointParameters {
        axis -1 0 0
        anchor 0.17 -0.68 -0.6
      }
      device [
        RotationalMotor {
          name "wheel4"
        }
      ]
      endPoint DEF WHEEL1 Solid {
        translation 0.16999999463314372 -0.6800179059860766 -0.5999122151255272
        rotation 0.7071072811859473 1.3267905276682114e-06 0.7071062811855495 3.1415900000000003
        children [
          DEF WHEEL Shape {
            appearance PBRAppearance {
            }
            geometry Cylinder {
              height 0.05
              radius 0.05
            }
          }
        ]
        name "Wheel4"
        boundingObject USE WHEEL
        physics Physics {
        }
      }
    }
    HingeJoint {
      jointParameters HingeJointParameters {
      }
      endPoint Solid {
        translation 0 0.155562 0.155563
        rotation 1 0 0 -0.785395307179586
        children [
          Shape {
            appearance PBRAppearance {
            }
            geometry Cylinder {
              height 0.5
              radius 0.01
            }
          }
        ]
      }
    }
  ]
}
Robot {
  translation -1.99593 0.330197 0.1
  rotation 0 0 1 -5.307179586466759e-06
  children [
    Solid {
      translation 0 0 0.5
      children [
        Shape {
          appearance PBRAppearance {
            baseColor 1 1 0
            metalness 0
          }
          geometry Box {
            size 1.6 0.1 1
          }
        }
      ]
      name "solid(4)"
      boundingObject Box {
        size 1.6 0.1 1
      }
    }
    DistanceSensor {
      translation -0.1 0.03 0.01
      rotation 0 0 1 2.85189
      children [
        DEF sensor Shape {
          appearance PBRAppearance {
            baseColor 0 0 1
          }
          geometry Box {
            size 0.01 0.01 0.01
          }
        }
      ]
      name "ds_right"
      boundingObject USE sensor
    }
    DistanceSensor {
      translation -0.1 -0.03 0.01
      rotation 0 0 -1 2.85189
      children [
        DEF sensor Shape {
          appearance PBRAppearance {
            baseColor 0 0 1
          }
          geometry Box {
            size 0.01 0.01 0.01
          }
        }
      ]
      name "ds_left"
      boundingObject USE sensor
    }
    HingeJoint {
      jointParameters HingeJointParameters {
        axis 0 1 0
        anchor 0.05 -0.06 0
      }
      device [
        RotationalMotor {
          name "wheel1"
        }
      ]
      endPoint Solid {
        translation 0.05 0.06 0
        rotation 0.5773489358556707 0.5773509358554487 -0.5773509358554487 2.0943999999999985
        children [
          DEF WHEEL Shape {
            appearance PBRAppearance {
              baseColor 0 1 0
            }
            geometry Cylinder {
              height 0.02
              radius 0.04
            }
          }
        ]
        boundingObject USE WHEEL
        physics Physics {
        }
      }
    }
    HingeJoint {
      jointParameters HingeJointParameters {
        axis 0 1 0
        anchor -0.05 0.06 0
      }
      device [
        RotationalMotor {
          name "wheel3"
        }
      ]
      endPoint Solid {
        translation -0.05 0.06 0
        rotation 0.5773489358415549 0.5773509358625064 -0.5773509358625064 2.0944000000211718
        children [
          DEF WHEEL Shape {
            appearance PBRAppearance {
            }
            geometry Cylinder {
              height 0.02
              radius 0.04
            }
          }
        ]
        name "solid(1)"
        boundingObject USE WHEEL
        physics Physics {
        }
      }
    }
    HingeJoint {
      jointParameters HingeJointParameters {
        axis 0 1 0
        anchor -0.05 -0.06 0
      }
      device [
        RotationalMotor {
          name "wheel2"
        }
      ]
      endPoint Solid {
        translation -0.05 -0.06 0
        rotation 0.5773489358382035 0.5773509358641821 -0.5773509358641821 2.0944000000261997
        children [
          DEF WHEEL Shape {
            appearance PBRAppearance {
            }
            geometry Cylinder {
              height 0.02
              radius 0.04
            }
          }
        ]
        name "solid(2)"
        boundingObject USE WHEEL
        physics Physics {
        }
      }
    }
    HingeJoint {
      jointParameters HingeJointParameters {
        axis 0 1 0
        anchor 0.05 -0.06 0
      }
      device [
        RotationalMotor {
          name "wheel4"
        }
      ]
      endPoint Solid {
        translation 0.05 -0.06 0
        rotation 0.5773489358381692 0.5773509358641989 -0.5773509358641996 2.094400000026252
        children [
          DEF WHEEL Shape {
            appearance PBRAppearance {
            }
            geometry Cylinder {
              height 0.02
              radius 0.04
            }
          }
        ]
        name "solid(3)"
        boundingObject USE WHEEL
        physics Physics {
        }
      }
    }
    DEF box Shape {
      geometry Box {
        size 0.2 0.1 0.06
      }
    }
  ]
  boundingObject USE box
  physics Physics {
  }
  controller "car_controller"
}
